Workbook

Sheet Q&A
A1: No | B1: Category | C1: Question | D1: Why we ask | E1: Priority | F1: Blocking | G1: Customer answer | H1: Status
A2: 1 | B2: data | C2: Các văn bản quy định được cập nhật bao lâu một lần và ai là người cập nhật? | D2: Quyết định cơ chế đồng bộ và đánh chỉ mục lại tài liệu. | E2: Mid | F2: No | H2: Open
A3: 2 | B3: accuracy | C3: Câu trả lời có bắt buộc kèm trích dẫn điều khoản và số trang không? | D3: Ảnh hưởng thiết kế phần hiển thị nguồn và cách chia đoạn tài liệu. | E3: Mid | F3: No | H3: Open
A4: 3 | B4: integration | C4: Công ty đang dùng hệ thống đăng nhập tập trung (SSO) nào? | D4: Xác định effort tích hợp phân quyền theo phòng ban. | E4: Mid | F4: No | H4: Open

Sheet WBS
A1: ID | B1: Phase | C1: Task | D1: Sub-task | E1: Type | F1: Priority | G1: Estimate (MD) | H1: Depends on | I1: Deliverable | J1: Note
A2: 1 | B2: PoC | C2: Giai đoạn PoC | G2: =SUM(G3,G6,G9,G12,G15,G18)
A3: 1.1 | B3: PoC | C3: Kick-off và quản lý PoC | G3: =SUM(G4,G5)
A4: 1.1.1 | B4: PoC | D4: Kick-off và quản lý PoC – phần 1 | E4: PM | F4: Mid | G4: 5 | I4: Kết quả: kick-off và quản lý poc
A5: 1.1.2 | B5: PoC | D5: Kick-off và quản lý PoC – phần 2 | E5: PM | F5: Mid | G5: 4 | I5: Kết quả: kick-off và quản lý poc
A6: 1.2 | B6: PoC | C6: Khảo sát dữ liệu & yêu cầu | G6: =SUM(G7,G8)
A7: 1.2.1 | B7: PoC | D7: Khảo sát dữ liệu & yêu cầu – phần 1 | E7: BA | F7: Mid | G7: 5 | I7: Kết quả: khảo sát dữ liệu & yêu cầu
A8: 1.2.2 | B8: PoC | D8: Khảo sát dữ liệu & yêu cầu – phần 2 | E8: BA | F8: Mid | G8: 4 | I8: Kết quả: khảo sát dữ liệu & yêu cầu
A9: 1.3 | B9: PoC | C9: Chuẩn bị dữ liệu mẫu | G9: =SUM(G10,G11) | H9: 1.2
A10: 1.3.1 | B10: PoC | D10: Chuẩn bị dữ liệu mẫu – phần 1 | E10: DATA | F10: Mid | G10: 4 | I10: Kết quả: chuẩn bị dữ liệu mẫu | J10: data_prep
A11: 1.3.2 | B11: PoC | D11: Chuẩn bị dữ liệu mẫu – phần 2 | E11: DATA | F11: Mid | G11: 4 | I11: Kết quả: chuẩn bị dữ liệu mẫu | J11: data_prep
A12: 1.4 | B12: PoC | C12: Dựng prototype Chat API | G12: =SUM(G13,G14) | H12: 1.2
A13: 1.4.1 | B13: PoC | D13: Dựng prototype Chat API – phần 1 | E13: AI | F13: High | G13: 4 | I13: Kết quả: dựng prototype chat api
A14: 1.4.2 | B14: PoC | D14: Dựng prototype Chat API – phần 2 | E14: AI | F14: High | G14: 4 | I14: Kết quả: dựng prototype chat api
A15: 1.5 | B15: PoC | C15: Đánh giá kết quả PoC | G15: =SUM(G16,G17) | H15: 1.2
A16: 1.5.1 | B16: PoC | D16: Đánh giá kết quả PoC – phần 1 | E16: AI | F16: High | G16: 4 | I16: Kết quả: đánh giá kết quả poc | J16: evaluation
A17: 1.5.2 | B17: PoC | D17: Đánh giá kết quả PoC – phần 2 | E17: AI | F17: High | G17: 4 | I17: Kết quả: đánh giá kết quả poc | J17: evaluation
A18: 1.6 | B18: PoC | C18: Test và nghiệm thu PoC | G18: =SUM(G19,G20) | H18: 1.3, 1.4, 1.5
A19: 1.6.1 | B19: PoC | D19: Test và nghiệm thu PoC – phần 1 | E19: QA | F19: High | G19: 4 | I19: Kết quả: test và nghiệm thu poc
A20: 1.6.2 | B20: PoC | D20: Test và nghiệm thu PoC – phần 2 | E20: QA | F20: High | G20: 4 | I20: Kết quả: test và nghiệm thu poc
B21: PoC | C21: Total PoC | G21: =SUM(G2)
A22: 2 | B22: MVP | C22: Giai đoạn MVP | G22: =SUM(G23,G26,G29,G32,G35,G38,G41,G44,G47)
A23: 2.1 | B23: MVP | C23: Quản lý dự án MVP | G23: =SUM(G24,G25) | H23: 1.6
A24: 2.1.1 | B24: MVP | D24: Quản lý dự án MVP – phần 1 | E24: PM | F24: Mid | G24: 9 | I24: Kết quả: quản lý dự án mvp
A25: 2.1.2 | B25: MVP | D25: Quản lý dự án MVP – phần 2 | E25: PM | F25: Mid | G25: 8 | I25: Kết quả: quản lý dự án mvp
A26: 2.2 | B26: MVP | C26: Phân tích & thiết kế chi tiết | G26: =SUM(G27,G28)
A27: 2.2.1 | B27: MVP | D27: Phân tích & thiết kế chi tiết – phần 1 | E27: BA | F27: Mid | G27: 9 | I27: Kết quả: phân tích & thiết kế chi tiết
A28: 2.2.2 | B28: MVP | D28: Phân tích & thiết kế chi tiết – phần 2 | E28: BA | F28: Mid | G28: 8 | I28: Kết quả: phân tích & thiết kế chi tiết
A29: 2.3 | B29: MVP | C29: Chuẩn bị & làm sạch dữ liệu | G29: =SUM(G30,G31) | H29: 2.2
A30: 2.3.1 | B30: MVP | D30: Chuẩn bị & làm sạch dữ liệu – phần 1 | E30: DATA | F30: Mid | G30: 9 | I30: Kết quả: chuẩn bị & làm sạch dữ liệu | J30: data_prep
A31: 2.3.2 | B31: MVP | D31: Chuẩn bị & làm sạch dữ liệu – phần 2 | E31: DATA | F31: Mid | G31: 8 | I31: Kết quả: chuẩn bị & làm sạch dữ liệu | J31: data_prep
A32: 2.4 | B32: MVP | C32: Xây dựng Chat API | G32: =SUM(G33,G34) | H32: 2.2
A33: 2.4.1 | B33: MVP | D33: Xây dựng Chat API – phần 1 | E33: AI | F33: High | G33: 9 | I33: Kết quả: xây dựng chat api
A34: 2.4.2 | B34: MVP | D34: Xây dựng Chat API – phần 2 | E34: AI | F34: High | G34: 8 | I34: Kết quả: xây dựng chat api
A35: 2.5 | B35: MVP | C35: Xây dựng Web chat | G35: =SUM(G36,G37) | H35: 2.2
A36: 2.5.1 | B36: MVP | D36: Xây dựng Web chat – phần 1 | E36: BE | F36: Mid | G36: 9 | I36: Kết quả: xây dựng web chat | J36: integration
A37: 2.5.2 | B37: MVP | D37: Xây dựng Web chat – phần 2 | E37: BE | F37: Mid | G37: 8 | I37: Kết quả: xây dựng web chat | J37: integration
A38: 2.6 | B38: MVP | C38: Giao diện người dùng | G38: =SUM(G39,G40) | H38: 2.2
A39: 2.6.1 | B39: MVP | D39: Giao diện người dùng – phần 1 | E39: FE | F39: Mid | G39: 9 | I39: Kết quả: giao diện người dùng
A40: 2.6.2 | B40: MVP | D40: Giao diện người dùng – phần 2 | E40: FE | F40: Mid | G40: 8 | I40: Kết quả: giao diện người dùng
...

Sheet Summary
A1: Phase | B1: AI | C1: BE | D1: FE | E1: QA | F1: BA | G1: PM | H1: INFRA | I1: DATA | J1: Total
A2: PoC | B2: =SUMIFS(WBS!$G:$G,WBS!$B:$B,$A2,WBS!$E:$E,B$1) | C2: =SUMIFS(WBS!$G:$G,WBS!$B:$B,$A2,WBS!$E:$E,C$1) | D2: =SUMIFS(WBS!$G:$G,WBS!$B:$B,$A2,WBS!$E:$E,D$1) | E2: =SUMIFS(WBS!$G:$G,WBS!$B:$B,$A2,WBS!$E:$E,E$1) | F2: =SUMIFS(WBS!$G:$G,WBS!$B:$B,$A2,WBS!$E:$E,F$1) | G2: =SUMIFS(WBS!$G:$G,WBS!$B:$B,$A2,WBS!$E:$E,G$1) | H2: =SUMIFS(WBS!$G:$G,WBS!$B:$B,$A2,WBS!$E:$E,H$1) | I2: =SUMIFS(WBS!$G:$G,WBS!$B:$B,$A2,WBS!$E:$E,I$1) | J2: =SUM(B2:I2)
A3: MVP | B3: =SUMIFS(WBS!$G:$G,WBS!$B:$B,$A3,WBS!$E:$E,B$1) | C3: =SUMIFS(WBS!$G:$G,WBS!$B:$B,$A3,WBS!$E:$E,C$1) | D3: =SUMIFS(WBS!$G:$G,WBS!$B:$B,$A3,WBS!$E:$E,D$1) | E3: =SUMIFS(WBS!$G:$G,WBS!$B:$B,$A3,WBS!$E:$E,E$1) | F3: =SUMIFS(WBS!$G:$G,WBS!$B:$B,$A3,WBS!$E:$E,F$1) | G3: =SUMIFS(WBS!$G:$G,WBS!$B:$B,$A3,WBS!$E:$E,G$1) | H3: =SUMIFS(WBS!$G:$G,WBS!$B:$B,$A3,WBS!$E:$E,H$1) | I3: =SUMIFS(WBS!$G:$G,WBS!$B:$B,$A3,WBS!$E:$E,I$1) | J3: =SUM(B3:I3)
A4: Production | B4: =SUMIFS(WBS!$G:$G,WBS!$B:$B,$A4,WBS!$E:$E,B$1) | C4: =SUMIFS(WBS!$G:$G,WBS!$B:$B,$A4,WBS!$E:$E,C$1) | D4: =SUMIFS(WBS!$G:$G,WBS!$B:$B,$A4,WBS!$E:$E,D$1) | E4: =SUMIFS(WBS!$G:$G,WBS!$B:$B,$A4,WBS!$E:$E,E$1) | F4: =SUMIFS(WBS!$G:$G,WBS!$B:$B,$A4,WBS!$E:$E,F$1) | G4: =SUMIFS(WBS!$G:$G,WBS!$B:$B,$A4,WBS!$E:$E,G$1) | H4: =SUMIFS(WBS!$G:$G,WBS!$B:$B,$A4,WBS!$E:$E,H$1) | I4: =SUMIFS(WBS!$G:$G,WBS!$B:$B,$A4,WBS!$E:$E,I$1) | J4: =SUM(B4:I4)
A5: Total | B5: =SUM(B2:B4) | C5: =SUM(C2:C4) | D5: =SUM(D2:D4) | E5: =SUM(E2:E4) | F5: =SUM(F2:F4) | G5: =SUM(G2:G4) | H5: =SUM(H2:H4) | I5: =SUM(I2:I4) | J5: =SUM(J2:J4)
A7: Assumptions
A8: • WBS sinh bởi mock LLM.
A10: Out of scope
A11: • Ứng dụng di động native (iOS/Android)
A12: • Tích hợp hệ thống ERP hiện có chưa được liệt kê trong requirements
A13: • Di chuyển (migrate) toàn bộ dữ liệu lịch sử (chỉ nạp dữ liệu mẫu trong PoC)

Sheet Master Schedule
A1: ID | B1: Task | C1: Phase | D1: Start | E1: End | F1: Days | G1: 26/10 | H1: 02/11 | I1: 09/11 | J1: 16/11 | K1: 23/11 | L1: 30/11 | M1: 07/12 | N1: 14/12 | O1: 21/12 | P1: 28/12 | Q1: 04/01 | R1: 11/01 | S1: 18/01 | T1: 25/01 | U1: 01/02 | V1: 08/02 | W1: 15/02 | X1: 22/02 | Y1: 01/03 | Z1: 08/03 | AA1: 15/03 | AB1: 22/03 | AC1: 29/03 | AD1: 05/04
B2: PoC | C2: PoC | D2: 46321 | E2: 46359 | F2: 29
A3: 1.1 | B3: Kick-off và quản lý PoC | C3: PoC | D3: 46321 | E3: 46331 | F3: 9
A4: 1.2 | B4: Khảo sát dữ liệu & yêu cầu | C4: PoC | D4: 46321 | E4: 46331 | F4: 9
A5: 1.3 | B5: Chuẩn bị dữ liệu mẫu | C5: PoC | D5: 46332 | E5: 46343 | F5: 8
A6: 1.4 | B6: Dựng prototype Chat API | C6: PoC | D6: 46332 | E6: 46337 | F6: 4
A7: 1.5 | B7: Đánh giá kết quả PoC | C7: PoC | D7: 46332 | E7: 46337 | F7: 4
A8: 1.6 | B8: Test và nghiệm thu PoC | C8: PoC | D8: 46344 | E8: 46353 | F8: 8
A9: M1 | B9: Kick-off (30%) | C9: PoC | D9: 46321 | E9: 46321 | F9: 0 | G9: ◆
A10: M2 | B10: Nghiệm thu PoC | C10: PoC | D10: 46359 | E10: 46359 | F10: 0 | L10: ◆
B11: MVP | C11: MVP | D11: 46360 | E11: 46441 | F11: 58
A12: 2.1 | B12: Quản lý dự án MVP | C12: MVP | D12: 46360 | E12: 46384 | F12: 17
A13: 2.2 | B13: Phân tích & thiết kế chi tiết | C13: MVP | D13: 46360 | E13: 46384 | F13: 17
A14: 2.3 | B14: Chuẩn bị & làm sạch dữ liệu | C14: MVP | D14: 46385 | E14: 46407 | F14: 17
A15: 2.4 | B15: Xây dựng Chat API | C15: MVP | D15: 46385 | E15: 46395 | F15: 9
A16: 2.5 | B16: Xây dựng Web chat | C16: MVP | D16: 46385 | E16: 46407 | F16: 17
A17: 2.6 | B17: Giao diện người dùng | C17: MVP | D17: 46385 | E17: 46407 | F17: 17
A18: 2.7 | B18: Bộ đánh giá chất lượng | C18: MVP | D18: 46385 | E18: 46394 | F18: 8
A19: 2.8 | B19: Test và nghiệm thu MVP | C19: MVP | D19: 46408 | E19: 46429 | F19: 16
A20: 2.9 | B20: Tài liệu và bàn giao | C20: MVP | D20: 46360 | E20: 46381 | F20: 16
A21: M3 | B21: Nghiệm thu MVP (40%) | C21: MVP | D21: 46441 | E21: 46441 | F21: 0 | X21: ◆
B22: Production | C22: Production | D22: 46442 | E22: 46486 | F22: 33
A23: 3.1 | B23: Quản lý triển khai – đợt 1 | C23: Production | D23: 46442 | E23: 46450 | F23: 7
A24: 3.2 | B24: Quản lý triển khai – đợt 2 | C24: Production | D24: 46442 | E24: 46450 | F24: 7
A25: 3.3 | B25: Hardening & bảo mật – đợt 1 | C25: Production | D25: 46451 | E25: 46461 | F25: 7
A26: 3.4 | B26: Hardening & bảo mật – đợt 2 | C26: Production | D26: 46451 | E26: 46461 | F26: 7
A27: 3.5 | B27: Mở rộng Vector index – đợt 1 | C27: Production | D27: 46451 | E27: 46461 | F27: 7
A28: 3.6 | B28: Mở rộng Vector index – đợt 2 | C28: Production | D28: 46451 | E28: 46461 | F28: 7
A29: 3.7 | B29: Giám sát & vận hành – đợt 1 | C29: Production | D29: 46451 | E29: 46461 | F29: 7
A30: 3.8 | B30: Giám sát & vận hành – đợt 2 | C30: Production | D30: 46451 | E30: 46461 | F30: 7
A31: 3.9 | B31: UAT và nghiệm thu – đợt 1 | C31: Production | D31: 46462 | E31: 46469 | F31: 6
A32: 3.10 | B32: UAT và nghiệm thu – đợt 2 | C32: Production | D32: 46462 | E32: 46469 | F32: 6
A33: 3.11 | B33: Đào tạo & bàn giao – đợt 1 | C33: Production | D33: 46442 | E33: 46449 | F33: 6
A34: 3.12 | B34: Đào tạo & bàn giao – đợt 2 | C34: Production | D34: 46442 | E34: 46449 | F34: 6
A35: M4 | B35: Go-live (30%) | C35: Production | D35: 46486 | E35: 46486 | F35: 0 | AD35: ◆
